<?xml version="1.0" encoding="UTF-8"?>
<testng-results skipped="0" failed="2" ignored="0" total="3" passed="1">
  <reporter-output>
  </reporter-output>
  <suite name="Suite" duration-ms="42428" started-at="2020-05-13T10:57:39Z" finished-at="2020-05-13T10:58:22Z">
    <groups>
    </groups>
    <test name="Test" duration-ms="42428" started-at="2020-05-13T10:57:39Z" finished-at="2020-05-13T10:58:22Z">
      <class name="org.fail.ExecutionClass">
        <test-method status="PASS" signature="launch()[pri:0, instance:org.fail.ExecutionClass@240237d2]" name="launch" is-config="true" duration-ms="12479" started-at="2020-05-13T10:57:39Z" finished-at="2020-05-13T10:57:52Z">
          <reporter-output>
          </reporter-output>
        </test-method> <!-- launch -->
        <test-method status="PASS" signature="test1()[pri:0, instance:org.fail.ExecutionClass@240237d2]" name="test1" duration-ms="4595" started-at="2020-05-13T10:57:52Z" finished-at="2020-05-13T10:57:56Z">
          <reporter-output>
          </reporter-output>
        </test-method> <!-- test1 -->
        <test-method status="PASS" signature="close()[pri:0, instance:org.fail.ExecutionClass@240237d2]" name="close" is-config="true" duration-ms="1504" started-at="2020-05-13T10:57:56Z" finished-at="2020-05-13T10:57:58Z">
          <reporter-output>
          </reporter-output>
        </test-method> <!-- close -->
        <test-method status="PASS" signature="launch()[pri:0, instance:org.fail.ExecutionClass@240237d2]" name="launch" is-config="true" duration-ms="6886" started-at="2020-05-13T10:57:58Z" finished-at="2020-05-13T10:58:05Z">
          <reporter-output>
          </reporter-output>
        </test-method> <!-- launch -->
        <test-method status="FAIL" signature="test2()[pri:0, instance:org.fail.ExecutionClass@240237d2]" name="test2" duration-ms="2547" started-at="2020-05-13T10:58:05Z" finished-at="2020-05-13T10:58:07Z">
          <exception class="java.lang.AssertionError">
            <message>
              <![CDATA[expected [true] but found [false]]]>
            </message>
            <full-stacktrace>
              <![CDATA[java.lang.AssertionError: expected [true] but found [false]
at org.testng.Assert.fail(Assert.java:96)
at org.testng.Assert.failNotEquals(Assert.java:776)
at org.testng.Assert.assertTrue(Assert.java:44)
at org.testng.Assert.assertTrue(Assert.java:54)
at org.fail.ExecutionClass.test2(ExecutionClass.java:35)
at sun.reflect.NativeMethodAccessorImpl.invoke0(Native Method)
at sun.reflect.NativeMethodAccessorImpl.invoke(Unknown Source)
at sun.reflect.DelegatingMethodAccessorImpl.invoke(Unknown Source)
at java.lang.reflect.Method.invoke(Unknown Source)
at org.testng.internal.MethodInvocationHelper.invokeMethod(MethodInvocationHelper.java:124)
at org.testng.internal.Invoker.invokeMethod(Invoker.java:583)
at org.testng.internal.Invoker.invokeTestMethod(Invoker.java:719)
at org.testng.internal.Invoker.invokeTestMethods(Invoker.java:989)
at org.testng.internal.TestMethodWorker.invokeTestMethods(TestMethodWorker.java:125)
at org.testng.internal.TestMethodWorker.run(TestMethodWorker.java:109)
at org.testng.TestRunner.privateRun(TestRunner.java:648)
at org.testng.TestRunner.run(TestRunner.java:505)
at org.testng.SuiteRunner.runTest(SuiteRunner.java:455)
at org.testng.SuiteRunner.runSequentially(SuiteRunner.java:450)
at org.testng.SuiteRunner.privateRun(SuiteRunner.java:415)
at org.testng.SuiteRunner.run(SuiteRunner.java:364)
at org.testng.SuiteRunnerWorker.runSuite(SuiteRunnerWorker.java:52)
at org.testng.SuiteRunnerWorker.run(SuiteRunnerWorker.java:84)
at org.testng.TestNG.runSuitesSequentially(TestNG.java:1208)
at org.testng.TestNG.runSuitesLocally(TestNG.java:1137)
at org.testng.TestNG.runSuites(TestNG.java:1049)
at org.testng.TestNG.run(TestNG.java:1017)
at org.testng.remote.AbstractRemoteTestNG.run(AbstractRemoteTestNG.java:115)
at org.testng.remote.RemoteTestNG.initAndRun(RemoteTestNG.java:251)
at org.testng.remote.RemoteTestNG.main(RemoteTestNG.java:77)
]]>
            </full-stacktrace>
          </exception> <!-- java.lang.AssertionError -->
          <reporter-output>
          </reporter-output>
        </test-method> <!-- test2 -->
        <test-method status="PASS" signature="close()[pri:0, instance:org.fail.ExecutionClass@240237d2]" name="close" is-config="true" duration-ms="801" started-at="2020-05-13T10:58:08Z" finished-at="2020-05-13T10:58:09Z">
          <reporter-output>
          </reporter-output>
        </test-method> <!-- close -->
        <test-method status="PASS" signature="launch()[pri:0, instance:org.fail.ExecutionClass@240237d2]" name="launch" is-config="true" duration-ms="6780" started-at="2020-05-13T10:58:09Z" finished-at="2020-05-13T10:58:15Z">
          <reporter-output>
          </reporter-output>
        </test-method> <!-- launch -->
        <test-method status="FAIL" signature="test3()[pri:0, instance:org.fail.ExecutionClass@240237d2]" name="test3" duration-ms="4647" started-at="2020-05-13T10:58:15Z" finished-at="2020-05-13T10:58:20Z">
          <exception class="java.lang.AssertionError">
            <message>
              <![CDATA[expected [true] but found [false]]]>
            </message>
            <full-stacktrace>
              <![CDATA[java.lang.AssertionError: expected [true] but found [false]
at org.testng.Assert.fail(Assert.java:96)
at org.testng.Assert.failNotEquals(Assert.java:776)
at org.testng.Assert.assertTrue(Assert.java:44)
at org.testng.Assert.assertTrue(Assert.java:54)
at org.fail.ExecutionClass.test3(ExecutionClass.java:41)
at sun.reflect.NativeMethodAccessorImpl.invoke0(Native Method)
at sun.reflect.NativeMethodAccessorImpl.invoke(Unknown Source)
at sun.reflect.DelegatingMethodAccessorImpl.invoke(Unknown Source)
at java.lang.reflect.Method.invoke(Unknown Source)
at org.testng.internal.MethodInvocationHelper.invokeMethod(MethodInvocationHelper.java:124)
at org.testng.internal.Invoker.invokeMethod(Invoker.java:583)
at org.testng.internal.Invoker.invokeTestMethod(Invoker.java:719)
at org.testng.internal.Invoker.invokeTestMethods(Invoker.java:989)
at org.testng.internal.TestMethodWorker.invokeTestMethods(TestMethodWorker.java:125)
at org.testng.internal.TestMethodWorker.run(TestMethodWorker.java:109)
at org.testng.TestRunner.privateRun(TestRunner.java:648)
at org.testng.TestRunner.run(TestRunner.java:505)
at org.testng.SuiteRunner.runTest(SuiteRunner.java:455)
at org.testng.SuiteRunner.runSequentially(SuiteRunner.java:450)
at org.testng.SuiteRunner.privateRun(SuiteRunner.java:415)
at org.testng.SuiteRunner.run(SuiteRunner.java:364)
at org.testng.SuiteRunnerWorker.runSuite(SuiteRunnerWorker.java:52)
at org.testng.SuiteRunnerWorker.run(SuiteRunnerWorker.java:84)
at org.testng.TestNG.runSuitesSequentially(TestNG.java:1208)
at org.testng.TestNG.runSuitesLocally(TestNG.java:1137)
at org.testng.TestNG.runSuites(TestNG.java:1049)
at org.testng.TestNG.run(TestNG.java:1017)
at org.testng.remote.AbstractRemoteTestNG.run(AbstractRemoteTestNG.java:115)
at org.testng.remote.RemoteTestNG.initAndRun(RemoteTestNG.java:251)
at org.testng.remote.RemoteTestNG.main(RemoteTestNG.java:77)
]]>
            </full-stacktrace>
          </exception> <!-- java.lang.AssertionError -->
          <reporter-output>
          </reporter-output>
        </test-method> <!-- test3 -->
        <test-method status="PASS" signature="close()[pri:0, instance:org.fail.ExecutionClass@240237d2]" name="close" is-config="true" duration-ms="1189" started-at="2020-05-13T10:58:21Z" finished-at="2020-05-13T10:58:22Z">
          <reporter-output>
          </reporter-output>
        </test-method> <!-- close -->
      </class> <!-- org.fail.ExecutionClass -->
    </test> <!-- Test -->
  </suite> <!-- Suite -->
</testng-results>
